Workbook

Sheet Leia-me
A1: Simulados MED / ENAMED 2026 — dados remontados a partir dos dashboards
A3: O que é este arquivo | B3: Os dois dashboards originais não continham dados em células: todas as abas estavam vazias e os números apareciam apenas como IMAGENS coladas (prints de tabelas dinâmicas) e como cache de gráficos. Este arquivo remonta esse conteúdo em tabelas de dados utilizáveis.
A4: Fontes | B4: Dashboard_Simulado_01__MED__ENAMED_2026.xlsx (16 imagens; 12 com dados) · Dashboard_Simulado_02__MED__ENAMED_2026.xlsx (20 imagens; 16 com dados) · Gabarito_Simulado_1_2026.pdf · Simulado_01_2026.pdf · Simulado_02_20261.pdf
A5: Como foi extraído | B5: 1) Nomes, acertos e %acertos dos alunos: lidos das imagens das abas '6ª/7ª/10ª/11ª Fase'. 2) % de acerto por questão: lidos das imagens das abas 'Base ...' e conferidos contra o cache numérico dos gráficos das abas Q1..Qn, que traz os valores exatos. 3) Distribuição de respostas por alternativa (A–E): extraída do cache dos gráficos.
A6: Conferência
A7: Simulado 02 | B7: Fecha exatamente: para cada uma das 4 fases, a soma dos acertos por questão é idêntica à soma dos acertos dos alunos (diferença = 0). Isso valida as 240 porcentagens e os 120 totais lidos nas imagens.
A8: Simulado 01 | B8: Fecha exatamente do mesmo modo, nas 4 fases (diferença = 0), usando a chave que o próprio dashboard aplicou. 38 das 39 questões analisadas coincidem com o gabarito oficial; a 39ª é a ressalva 1.
A9: Ressalva 1 — Questão 39 | B9: O gabarito oficial (PDF) indica D, mas todo o dashboard (gráficos, % de acerto e notas dos alunos) foi calculado com E. Pelo enunciado, E é a alternativa correta (definição de SRAG do Ministério da Saúde: síndrome gripal com dispneia, pressão persistente no tórax, SatO2 ≤94% ou cianose); D descreve critérios de agravamento em idosos. Ou seja, o dashboard está certo e o PDF do gabarito tem erro de digitação nessa questão. Esta planilha reproduz o dashboard: a coluna Gabarito traz D (oficial), mas os acertos são os que o dashboard contabilizou, com E. Se a intenção fosse mesmo D, a Q39 cairia de 14/23/22/19 acertos para 0/5/3/3 e todas as notas mudariam — por isso a divergência precisa ser decidida antes de usar estes números.
A10: Ressalva 2 — Questão 24 | B10: A Questão 24 foi anulada no Simulado 01: não tem aba, nem gráfico, nem linha nas imagens, e o %Acertos dos alunos é calculado sobre 39 questões. Não sobrou nenhum dado dela: a soma dos acertos por questão bate exatamente com a soma dos acertos dos alunos sem a Q24. Ela aparece nas abas de questões apenas como linha marcada em amarelo, sem valores.
A11: Ressalva 3 — Gabarito do S02 | B11: O PDF do Simulado 02 vem com a folha de gabarito em branco. O gabarito das 60 questões foi deduzido cruzando o cache dos gráficos com as % das imagens: em todas as 60 questões uma única alternativa reproduz a % de acerto simultaneamente nas 4 fases, e o resultado fecha com a soma de acertos dos alunos. Gabarito deduzido: DBCCCDCBDADCBABBACCBACDCBADABBACADABAABCCDCBABBCADCCEEBDEDBC
A12: Ressalva 4 — nomes | B12: Dois nomes apareciam truncados na imagem da 10ª Fase do Simulado 01 ('Lucas Eduardo dos Santos Vian…' e 'Maria Eduarda Medeiros Macha…'); foram completados pela lista do Simulado 02.
A14: Abas
A15: Alunos | B15: Uma linha por aluno por simulado: fase, acertos, % e posição.
A16: Questões | B16: Uma linha por questão: gabarito e acertos/% por fase, % geral e dificuldade.
A17: Questão x Fase | B17: Mesma informação em formato longo, pronta para tabela dinâmica.
A18: Distribuição respostas | B18: Nº e % de alunos em cada alternativa A–E, por questão e por fase.
A19: Resumo por fase | B19: Estatísticas descritivas de cada fase em cada simulado.
A20: Comparativo S01 x S02 | B20: Alunos presentes nos dois simulados e variação em pontos percentuais.
A22: Observação | B22: Percentuais são fórmulas sobre as contagens; ao alterar um número de acertos, o resto recalcula.

Sheet Alunos
A1: Simulado | B1: Fase | C1: Nome do acadêmico | D1: Acertos | E1: Base do % (questões) | F1: % Acertos | G1: Posição na fase | H1: Posição no simulado
A2: Simulado 01 | B2: 6ª Fase | C2: Amanda Figueiredo Meneghetti | D2: 23 | E2: 39 | F2: =IF(E2=0,"",D2/E2) | G2: =SUMPRODUCT(($A$2:$A$239=A2)*($B$2:$B$239=B2)*($D$2:$D$239>D2))+1 | H2: =SUMPRODUCT(($A$2:$A$239=A2)*($D$2:$D$239>D2))+1
A3: Simulado 01 | B3: 6ª Fase | C3: Amanda de Matos da Silva | D3: 26 | E3: 39 | F3: =IF(E3=0,"",D3/E3) | G3: =SUMPRODUCT(($A$2:$A$239=A3)*($B$2:$B$239=B3)*($D$2:$D$239>D3))+1 | H3: =SUMPRODUCT(($A$2:$A$239=A3)*($D$2:$D$239>D3))+1
A4: Simulado 01 | B4: 6ª Fase | C4: Bárbara Letícia Armiliato | D4: 22 | E4: 39 | F4: =IF(E4=0,"",D4/E4) | G4: =SUMPRODUCT(($A$2:$A$239=A4)*($B$2:$B$239=B4)*($D$2:$D$239>D4))+1 | H4: =SUMPRODUCT(($A$2:$A$239=A4)*($D$2:$D$239>D4))+1
A5: Simulado 01 | B5: 6ª Fase | C5: Carla Bonacolsi | D5: 18 | E5: 39 | F5: =IF(E5=0,"",D5/E5) | G5: =SUMPRODUCT(($A$2:$A$239=A5)*($B$2:$B$239=B5)*($D$2:$D$239>D5))+1 | H5: =SUMPRODUCT(($A$2:$A$239=A5)*($D$2:$D$239>D5))+1
A6: Simulado 01 | B6: 6ª Fase | C6: Cauã Eduardo Eibel | D6: 22 | E6: 39 | F6: =IF(E6=0,"",D6/E6) | G6: =SUMPRODUCT(($A$2:$A$239=A6)*($B$2:$B$239=B6)*($D$2:$D$239>D6))+1 | H6: =SUMPRODUCT(($A$2:$A$239=A6)*($D$2:$D$239>D6))+1
A7: Simulado 01 | B7: 6ª Fase | C7: Eduardo Jacó Goedert | D7: 19 | E7: 39 | F7: =IF(E7=0,"",D7/E7) | G7: =SUMPRODUCT(($A$2:$A$239=A7)*($B$2:$B$239=B7)*($D$2:$D$239>D7))+1 | H7: =SUMPRODUCT(($A$2:$A$239=A7)*($D$2:$D$239>D7))+1
A8: Simulado 01 | B8: 6ª Fase | C8: Giacomo João Mondini | D8: 23 | E8: 39 | F8: =IF(E8=0,"",D8/E8) | G8: =SUMPRODUCT(($A$2:$A$239=A8)*($B$2:$B$239=B8)*($D$2:$D$239>D8))+1 | H8: =SUMPRODUCT(($A$2:$A$239=A8)*($D$2:$D$239>D8))+1
A9: Simulado 01 | B9: 6ª Fase | C9: Heitor Antônio Giehl | D9: 19 | E9: 39 | F9: =IF(E9=0,"",D9/E9) | G9: =SUMPRODUCT(($A$2:$A$239=A9)*($B$2:$B$239=B9)*($D$2:$D$239>D9))+1 | H9: =SUMPRODUCT(($A$2:$A$239=A9)*($D$2:$D$239>D9))+1
A10: Simulado 01 | B10: 6ª Fase | C10: João Otávio Correa Machado | D10: 26 | E10: 39 | F10: =IF(E10=0,"",D10/E10) | G10: =SUMPRODUCT(($A$2:$A$239=A10)*($B$2:$B$239=B10)*($D$2:$D$239>D10))+1 | H10: =SUMPRODUCT(($A$2:$A$239=A10)*($D$2:$D$239>D10))+1
A11: Simulado 01 | B11: 6ª Fase | C11: Larissa Raimundo | D11: 17 | E11: 39 | F11: =IF(E11=0,"",D11/E11) | G11: =SUMPRODUCT(($A$2:$A$239=A11)*($B$2:$B$239=B11)*($D$2:$D$239>D11))+1 | H11: =SUMPRODUCT(($A$2:$A$239=A11)*($D$2:$D$239>D11))+1
A12: Simulado 01 | B12: 6ª Fase | C12: Leandro Batista de Oliveira | D12: 25 | E12: 39 | F12: =IF(E12=0,"",D12/E12) | G12: =SUMPRODUCT(($A$2:$A$239=A12)*($B$2:$B$239=B12)*($D$2:$D$239>D12))+1 | H12: =SUMPRODUCT(($A$2:$A$239=A12)*($D$2:$D$239>D12))+1
A13: Simulado 01 | B13: 6ª Fase | C13: Léo Jaime Xavier da Silva | D13: 22 | E13: 39 | F13: =IF(E13=0,"",D13/E13) | G13: =SUMPRODUCT(($A$2:$A$239=A13)*($B$2:$B$239=B13)*($D$2:$D$239>D13))+1 | H13: =SUMPRODUCT(($A$2:$A$239=A13)*($D$2:$D$239>D13))+1
... A239: Simulado 02 | B239: 11ª Fase | C239: Yasmin Rafaela Braun | D239: 34 | E239: 60 | F239: =IF(E239=0,"",D239/E239) | G239: =SUMPRODUCT(($A$2:$A$239=A239)*($B$2:$B$239=B239)*($D$2:$D$239>D239))+1 | H239: =SUMPRODUCT(($A$2:$A$239=A239)*($D$2:$D$239>D239))+1

Sheet Questões
A1: Simulado | B1: Questão | C1: Gabarito (chave do dashboard) | D1: Acertos 6ª Fase | E1: % 6ª Fase | F1: Acertos 7ª Fase | G1: % 7ª Fase | H1: Acertos 10ª Fase | I1: % 10ª Fase | J1: Acertos 11ª Fase | K1: % 11ª Fase | L1: Total de acertos | M1: Total de alunos | N1: % geral | O1: Dificuldade | P1: Situação
A2: Simulado 01 | B2: 1 | C2: E | D2: 24 | E2: =D2/27 | F2: 32 | G2: =F2/33 | H2: 31 | I2: =H2/31 | J2: 27 | K2: =J2/27 | L2: =D2+F2+H2+J2 | M2: 118 | N2: =IF(M2="","",L2/M2) | O2: =IF(N2>=0.85,"Muito fácil",IF(N2>=0.7,"Fácil",IF(N2>=0.4,"Médio",IF(N2>=0.2,"Difícil","Muito difícil")))) | P2: OK
A3: Simulado 01 | B3: 2 | C3: E | D3: 23 | E3: =D3/27 | F3: 33 | G3: =F3/33 | H3: 26 | I3: =H3/31 | J3: 26 | K3: =J3/27 | L3: =D3+F3+H3+J3 | M3: 118 | N3: =IF(M3="","",L3/M3) | O3: =IF(N3>=0.85,"Muito fácil",IF(N3>=0.7,"Fácil",IF(N3>=0.4,"Médio",IF(N3>=0.2,"Difícil","Muito difícil")))) | P3: OK
A4: Simulado 01 | B4: 3 | C4: E | D4: 13 | E4: =D4/27 | F4: 25 | G4: =F4/33 | H4: 18 | I4: =H4/31 | J4: 17 | K4: =J4/27 | L4: =D4+F4+H4+J4 | M4: 118 | N4: =IF(M4="","",L4/M4) | O4: =IF(N4>=0.85,"Muito fácil",IF(N4>=0.7,"Fácil",IF(N4>=0.4,"Médio",IF(N4>=0.2,"Difícil","Muito difícil")))) | P4: OK
A5: Simulado 01 | B5: 4 | C5: D | D5: 19 | E5: =D5/27 | F5: 19 | G5: =F5/33 | H5: 13 | I5: =H5/31 | J5: 15 | K5: =J5/27 | L5: =D5+F5+H5+J5 | M5: 118 | N5: =IF(M5="","",L5/M5) | O5: =IF(N5>=0.85,"Muito fácil",IF(N5>=0.7,"Fácil",IF(N5>=0.4,"Médio",IF(N5>=0.2,"Difícil","Muito difícil")))) | P5: OK
A6: Simulado 01 | B6: 5 | C6: A | D6: 6 | E6: =D6/27 | F6: 14 | G6: =F6/33 | H6: 16 | I6: =H6/31 | J6: 12 | K6: =J6/27 | L6: =D6+F6+H6+J6 | M6: 118 | N6: =IF(M6="","",L6/M6) | O6: =IF(N6>=0.85,"Muito fácil",IF(N6>=0.7,"Fácil",IF(N6>=0.4,"Médio",IF(N6>=0.2,"Difícil","Muito difícil")))) | P6: OK
A7: Simulado 01 | B7: 6 | C7: B | D7: 2 | E7: =D7/27 | F7: 4 | G7: =F7/33 | H7: 3 | I7: =H7/31 | J7: 9 | K7: =J7/27 | L7: =D7+F7+H7+J7 | M7: 118 | N7: =IF(M7="","",L7/M7) | O7: =IF(N7>=0.85,"Muito fácil",IF(N7>=0.7,"Fácil",IF(N7>=0.4,"Médio",IF(N7>=0.2,"Difícil","Muito difícil")))) | P7: OK
A8: Simulado 01 | B8: 7 | C8: D | D8: 8 | E8: =D8/27 | F8: 8 | G8: =F8/33 | H8: 7 | I8: =H8/31 | J8: 12 | K8: =J8/27 | L8: =D8+F8+H8+J8 | M8: 118 | N8: =IF(M8="","",L8/M8) | O8: =IF(N8>=0.85,"Muito fácil",IF(N8>=0.7,"Fácil",IF(N8>=0.4,"Médio",IF(N8>=0.2,"Difícil","Muito difícil")))) | P8: OK
A9: Simulado 01 | B9: 8 | C9: E | D9: 4 | E9: =D9/27 | F9: 1 | G9: =F9/33 | H9: 1 | I9: =H9/31 | J9: 0 | K9: =J9/27 | L9: =D9+F9+H9+J9 | M9: 118 | N9: =IF(M9="","",L9/M9) | O9: =IF(N9>=0.85,"Muito fácil",IF(N9>=0.7,"Fácil",IF(N9>=0.4,"Médio",IF(N9>=0.2,"Difícil","Muito difícil")))) | P9: OK
A10: Simulado 01 | B10: 9 | C10: E | D10: 24 | E10: =D10/27 | F10: 30 | G10: =F10/33 | H10: 28 | I10: =H10/31 | J10: 24 | K10: =J10/27 | L10: =D10+F10+H10+J10 | M10: 118 | N10: =IF(M10="","",L10/M10) | O10: =IF(N10>=0.85,"Muito fácil",IF(N10>=0.7,"Fácil",IF(N10>=0.4,"Médio",IF(N10>=0.2,"Difícil","Muito difícil")))) | P10: OK
A11: Simulado 01 | B11: 10 | C11: B | D11: 22 | E11: =D11/27 | F11: 25 | G11: =F11/33 | H11: 27 | I11: =H11/31 | J11: 21 | K11: =J11/27 | L11: =D11+F11+H11+J11 | M11: 118 | N11: =IF(M11="","",L11/M11) | O11: =IF(N11>=0.85,"Muito fácil",IF(N11>=0.7,"Fácil",IF(N11>=0.4,"Médio",IF(N11>=0.2,"Difícil","Muito difícil")))) | P11: OK
A12: Simulado 01 | B12: 11 | C12: C | D12: 3 | E12: =D12/27 | F12: 9 | G12: =F12/33 | H12: 6 | I12: =H12/31 | J12: 2 | K12: =J12/27 | L12: =D12+F12+H12+J12 | M12: 118 | N12: =IF(M12="","",L12/M12) | O12: =IF(N12>=0.85,"Muito fácil",IF(N12>=0.7,"Fácil",IF(N12>=0.4,"Médio",IF(N12>=0.2,"Difícil","Muito difícil")))) | P12: OK
A13: Simulado 01 | B13: 12 | C13: A | D13: 13 | E13: =D13/27 | F13: 11 | G13: =F13/33 | H13: 14 | I13: =H13/31 | J13: 16 | K13: =J13/27 | L13: =D13+F13+H13+J13 | M13: 118 | N13: =IF(M13="","",L13/M13) | O13: =IF(N13>=0.85,"Muito fácil",IF(N13>=0.7,"Fácil",IF(N13>=0.4,"Médio",IF(N13>=0.2,"Difícil","Muito difícil")))) | P13: OK
... A24: Simulado 01 | B24: 23 | C24: D | D24: 14 | E24: =D24/27 | F24: 16 | G24: =F24/33 | H24: 29 | I24: =H24/31 | J24: 21 | K24: =J24/27 | L24: =D24+F24+H24+J24 | M24: 118 | N24: =IF(M24="","",L24/M24) | O24: =IF(N24>=0.85,"Muito fácil",IF(N24>=0.7,"Fácil",IF(N24>=0.4,"Médio",IF(N24>=0.2,"Difícil","Muito difícil")))) | P24: OK
A25: Simulado 01 | B25: 24 | C25: A | P25: ANULADA - sem dados no dashboard
A26: Simulado 01 | B26: 25 | C26: E | D26: 14 | E26: =D26/27 | F26: 19 | G26: =F26/33 | H26: 19 | I26: =H26/31 | J26: 16 | K26: =J26/27 | L26: =D26+F26+H26+J26 | M26: 118 | N26: =IF(M26="","",L26/M26) | O26: =IF(N26>=0.85,"Muito fácil",IF(N26>=0.7,"Fácil",IF(N26>=0.4,"Médio",IF(N26>=0.2,"Difícil","Muito difícil")))) | P26: OK
A27: Simulado 01 | B27: 26 | C27: D | D27: 19 | E27: =D27/27 | F27: 25 | G27: =F27/33 | H27: 24 | I27: =H27/31 | J27: 23 | K27: =J27/27 | L27: =D27+F27+H27+J27 | M27: 118 | N27: =IF(M27="","",L27/M27) | O27: =IF(N27>=0.85,"Muito fácil",IF(N27>=0.7,"Fácil",IF(N27>=0.4,"Médio",IF(N27>=0.2,"Difícil","Muito difícil")))) | P27: OK
A28: Simulado 01 | B28: 27 | C28: E | D28: 9 | E28: =D28/27 | F28: 16 | G28: =F28/33 | H28: 17 | I28: =H28/31 | J28: 12 | K28: =J28/27 | L28: =D28+F28+H28+J28 | M28: 118 | N28: =IF(M28="","",L28/M28) | O28: =IF(N28>=0.85,"Muito fácil",IF(N28>=0.7,"Fácil",IF(N28>=0.4,"Médio",IF(N28>=0.2,"Difícil","Muito difícil")))) | P28: OK
A29: Simulado 01 | B29: 28 | C29: D | D29: 25 | E29: =D29/27 | F29: 31 | G29: =F29/33 | H29: 31 | I29: =H29/31 | J29: 26 | K29: =J29/27 | L29: =D29+F29+H29+J29 | M29: 118 | N29: =IF(M29="","",L29/M29) | O29: =IF(N29>=0.85,"Muito fácil",IF(N29>=0.7,"Fácil",IF(N29>=0.4,"Médio",IF(N29>=0.2,"Difícil","Muito difícil")))) | P29: OK
A30: Simulado 01 | B30: 29 | C30: D | D30: 26 | E30: =D30/27 | F30: 29 | G30: =F30/33 | H30: 30 | I30: =H30/31 | J30: 26 | K30: =J30/27 | L30: =D30+F30+H30+J30 | M30: 118 | N30: =IF(M30="","",L30/M30) | O30: =IF(N30>=0.85,"Muito fácil",IF(N30>=0.7,"Fácil",IF(N30>=0.4,"Médio",IF(N30>=0.2,"Difícil","Muito difícil")))) | P30: OK
A31: Simulado 01 | B31: 30 | C31: C | D31: 21 | E31: =D31/27 | F31: 23 | G31: =F31/33 | H31: 25 | I31: =H31/31 | J31: 24 | K31: =J31/27 | L31: =D31+F31+H31+J31 | M31: 118 | N31: =IF(M31="","",L31/M31) | O31: =IF(N31>=0.85,"Muito fácil",IF(N31>=0.7,"Fácil",IF(N31>=0.4,"Médio",IF(N31>=0.2,"Difícil","Muito difícil")))) | P31: OK
A32: Simulado 01 | B32: 31 | C32: A | D32: 19 | E32: =D32/27 | F32: 22 | G32: =F32/33 | H32: 20 | I32: =H32/31 | J32: 24 | K32: =J32/27 | L32: =D32+F32+H32+J32 | M32: 118 | N32: =IF(M32="","",L32/M32) | O32: =IF(N32>=0.85,"Muito fácil",IF(N32>=0.7,"Fácil",IF(N32>=0.4,"Médio",IF(N32>=0.2,"Difícil","Muito difícil")))) | P32: OK
A33: Simulado 01 | B33: 32 | C33: A | D33: 16 | E33: =D33/27 | F33: 21 | G33: =F33/33 | H33: 17 | I33: =H33/31 | J33: 12 | K33: =J33/27 | L33: =D33+F33+H33+J33 | M33: 118 | N33: =IF(M33="","",L33/M33) | O33: =IF(N33>=0.85,"Muito fácil",IF(N33>=0.7,"Fácil",IF(N33>=0.4,"Médio",IF(N33>=0.2,"Difícil","Muito difícil")))) | P33: OK
A34: Simulado 01 | B34: 33 | C34: A | D34: 20 | E34: =D34/27 | F34: 29 | G34: =F34/33 | H34: 24 | I34: =H34/31 | J34: 24 | K34: =J34/27 | L34: =D34+F34+H34+J34 | M34: 118 | N34: =IF(M34="","",L34/M34) | O34: =IF(N34>=0.85,"Muito fácil",IF(N34>=0.7,"Fácil",IF(N34>=0.4,"Médio",IF(N34>=0.2,"Difícil","Muito difícil")))) | P34: OK
A35: Simulado 01 | B35: 34 | C35: C | D35: 24 | E35: =D35/27 | F35: 31 | G35: =F35/33 | H35: 30 | I35: =H35/31 | J35: 26 | K35: =J35/27 | L35: =D35+F35+H35+J35 | M35: 118 | N35: =IF(M35="","",L35/M35) | O35: =IF(N35>=0.85,"Muito fácil",IF(N35>=0.7,"Fácil",IF(N35>=0.4,"Médio",IF(N35>=0.2,"Difícil","Muito difícil")))) | P35: OK
A36: Simulado 01 | B36: 35 | C36: A | D36: 21 | E36: =D36/27 | F36: 22 | G36: =F36/33 | H36: 27 | I36: =H36/31 | J36: 23 | K36: =J36/27 | L36: =D36+F36+H36+J36 | M36: 118 | N36: =IF(M36="","",L36/M36) | O36: =IF(N36>=0.85,"Muito fácil",IF(N36>=0.7,"Fácil",IF(N36>=0.4,"Médio",IF(N36>=0.2,"Difícil","Muito difícil")))) | P36: OK
A37: Simulado 01 | B37: 36 | C37: B | D37: 25 | E37: =D37/27 | F37: 32 | G37: =F37/33 | H37: 30 | I37: =H37/31 | J37: 24 | K37: =J37/27 | L37: =D37+F37+H37+J37 | M37: 118 | N37: =IF(M37="","",L37/M37) | O37: =IF(N37>=0.85,"Muito fácil",IF(N37>=0.7,"Fácil",IF(N37>=0.4,"Médio",IF(N37>=0.2,"Difícil","Muito difícil")))) | P37: OK
... A41: Simulado 01 | B41: 40 | C41: B | D41: 8 | E41: =D41/27 | F41: 7 | G41: =F41/33 | H41: 11 | I41: =H41/31 | J41: 17 | K41: =J41/27 | L41: =D41+F41+H41+J41 | M41: 118 | N41: =IF(M41="","",L41/M41) | O41: =IF(N41>=0.85,"Muito fácil",IF(N41>=0.7,"Fácil",IF(N41>=0.4,"Médio",IF(N41>=0.2,"Difícil","Muito difícil")))) | P41: OK
A42: Simulado 02 | B42: 1 | C42: D | D42: 4 | E42: =D42/28 | F42: 4 | G42: =F42/32 | H42: 8 | I42: =H42/31 | J42: 15 | K42: =J42/29 | L42: =D42+F42+H42+J42 | M42: 120 | N42: =IF(M42="","",L42/M42) | O42: =IF(N42>=0.85,"Muito fácil",IF(N42>=0.7,"Fácil",IF(N42>=0.4,"Médio",IF(N42>=0.2,"Difícil","Muito difícil")))) | P42: OK
A43: Simulado 02 | B43: 2 | C43: B | D43: 20 | E43: =D43/28 | F43: 21 | G43: =F43/32 | H43: 21 | I43: =H43/31 | J43: 21 | K43: =J43/29 | L43: =D43+F43+H43+J43 | M43: 120 | N43: =IF(M43="","",L43/M43) | O43: =IF(N43>=0.85,"Muito fácil",IF(N43>=0.7,"Fácil",IF(N43>=0.4,"Médio",IF(N43>=0.2,"Difícil","Muito difícil")))) | P43: OK
A44: Simulado 02 | B44: 3 | C44: C | D44: 25 | E44: =D44/28 | F44: 30 | G44: =F44/32 | H44: 28 | I44: =H44/31 | J44: 28 | K44: =J44/29 | L44: =D44+F44+H44+J44 | M44: 120 | N44: =IF(M44="","",L44/M44) | O44: =IF(N44>=0.85,"Muito fácil",IF(N44>=0.7,"Fácil",IF(N44>=0.4,"Médio",IF(N44>=0.2,"Difícil","Muito difícil")))) | P44: OK
A45: Simulado 02 | B45: 4 | C45: C | D45: 14 | E45: =D45/28 | F45: 11 | G45: =F45/32 | H45: 17 | I45: =H45/31 | J45: 14 | K45: =J45/29 | L45: =D45+F45+H45+J45 | M45: 120 | N45: =IF(M45="","",L45/M45) | O45: =IF(N45>=0.85,"Muito fácil",IF(N45>=0.7,"Fácil",IF(N45>=0.4,"Médio",IF(N45>=0.2,"Difícil","Muito difícil")))) | P45: OK
A46: Simulado 02 | B46: 5 | C46: C | D46: 19 | E46: =D46/28 | F46: 20 | G46: =F46/32 | H46: 10 | I46: =H46/31 | J46: 19 | K46: =J46/29 | L46: =D46+F46+H46+J46 | M46: 120 | N46: =IF(M46="","",L46/M46) | O46: =IF(N46>=0.85,"Muito fácil",IF(N46>=0.7,"Fácil",IF(N46>=0.4,"Médio",IF(N46>=0.2,"Difícil","Muito difícil")))) | P46: OK
A47: Simulado 02 | B47: 6 | C47: D | D47: 15 | E47: =D47/28 | F47: 25 | G47: =F47/32 | H47: 22 | I47: =H47/31 | J47: 21 | K47: =J47/29 | L47: =D47+F47+H47+J47 | M47: 120 | N47: =IF(M47="","",L47/M47) | O47: =IF(N47>=0.85,"Muito fácil",IF(N47>=0.7,"Fácil",IF(N47>=0.4,"Médio",IF(N47>=0.2,"Difícil","Muito difícil")))) | P47: OK
A48: Simulado 02 | B48: 7 | C48: C | D48: 21 | E48: =D48/28 | F48: 27 | G48: =F48/32 | H48: 26 | I48: =H48/31 | J48: 23 | K48: =J48/29 | L48: =D48+F48+H48+J48 | M48: 120 | N48: =IF(M48="","",L48/M48) | O48: =IF(N48>=0.85,"Muito fácil",IF(N48>=0.7,"Fácil",IF(N48>=0.4,"Médio",IF(N48>=0.2,"Difícil","Muito difícil")))) | P48: OK
A49: Simulado 02 | B49: 8 | C49: B | D49: 21 | E49: =D49/28 | F49: 22 | G49: =F49/32 | H49: 25 | I49: =H49/31 | J49: 24 | K49: =J49/29 | L49: =D49+F49+H49+J49 | M49: 120 | N49: =IF(M49="","",L49/M49) | O49: =IF(N49>=0.85,"Muito fácil",IF(N49>=0.7,"Fácil",IF(N49>=0.4,"Médio",IF(N49>=0.2,"Difícil","Muito difícil")))) | P49: OK
A50: Simulado 02 | B50: 9 | C50: D | D50: 21 | E50: =D50/28 | F50: 27 | G50: =F50/32 | H50: 23 | I50: =H50/31 | J50: 23 | K50: =J50/29 | L50: =D50+F50+H50+J50 | M50: 120 | N50: =IF(M50="","",L50/M50) | O50: =IF(N50>=0.85,"Muito fácil",IF(N50>=0.7,"Fácil",IF(N50>=0.4,"Médio",IF(N50>=0.2,"Difícil","Muito difícil")))) | P50: OK
A51: Simulado 02 | B51: 10 | C51: A | D51: 10 | E51: =D51/28 | F51: 6 | G51: =F51/32 | H51: 9 | I51: =H51/31 | J51: 5 | K51: =J51/29 | L51: =D51+F51+H51+J51 | M51: 120 | N51: =IF(M51="","",L51/M51) | O51: =IF(N51>=0.85,"Muito fácil",IF(N51>=0.7,"Fácil",IF(N51>=0.4,"Médio",IF(N51>=0.2,"Difícil","Muito difícil")))) | P51: OK
A52: Simulado 02 | B52: 11 | C52: D | D52: 10 | E52: =D52/28 | F52: 12 | G52: =F52/32 | H52: 19 | I52: =H52/31 | J52: 21 | K52: =J52/29 | L52: =D52+F52+H52+J52 | M52: 120 | N52: =IF(M52="","",L52/M52) | O52: =IF(N52>=0.85,"Muito fácil",IF(N52>=0.7,"Fácil",IF(N52>=0.4,"Médio",IF(N52>=0.2,"Difícil","Muito difícil")))) | P52: OK
A53: Simulado 02 | B53: 12 | C53: C | D53: 10 | E53: =D53/28 | F53: 8 | G53: =F53/32 | H53: 5 | I53: =H53/31 | J53: 14 | K53: =J53/29 | L53: =D53+F53+H53+J53 | M53: 120 | N53: =IF(M53="","",L53/M53) | O53: =IF(N53>=0.85,"Muito fácil",IF(N53>=0.7,"Fácil",IF(N53>=0.4,"Médio",IF(N53>=0.2,"Difícil","Muito difícil")))) | P53: OK
...

Sheet Questão x Fase
A1: Simulado | B1: Questão | C1: Fase | D1: Gabarito (chave do dashboard) | E1: Alunos na fase | F1: Acertos | G1: % de acerto | H1: Situação
A2: Simulado 01 | B2: 1 | C2: 6ª Fase | D2: E | E2: 27 | F2: 24 | G2: =IF(E2=0,"",F2/E2) | H2: OK
A3: Simulado 01 | B3: 1 | C3: 7ª Fase | D3: E | E3: 33 | F3: 32 | G3: =IF(E3=0,"",F3/E3) | H3: OK
A4: Simulado 01 | B4: 1 | C4: 10ª Fase | D4: E | E4: 31 | F4: 31 | G4: =IF(E4=0,"",F4/E4) | H4: OK
A5: Simulado 01 | B5: 1 | C5: 11ª Fase | D5: E | E5: 27 | F5: 27 | G5: =IF(E5=0,"",F5/E5) | H5: OK
A6: Simulado 01 | B6: 2 | C6: 6ª Fase | D6: E | E6: 27 | F6: 23 | G6: =IF(E6=0,"",F6/E6) | H6: OK
A7: Simulado 01 | B7: 2 | C7: 7ª Fase | D7: E | E7: 33 | F7: 33 | G7: =IF(E7=0,"",F7/E7) | H7: OK
A8: Simulado 01 | B8: 2 | C8: 10ª Fase | D8: E | E8: 31 | F8: 26 | G8: =IF(E8=0,"",F8/E8) | H8: OK
A9: Simulado 01 | B9: 2 | C9: 11ª Fase | D9: E | E9: 27 | F9: 26 | G9: =IF(E9=0,"",F9/E9) | H9: OK
A10: Simulado 01 | B10: 3 | C10: 6ª Fase | D10: E | E10: 27 | F10: 13 | G10: =IF(E10=0,"",F10/E10) | H10: OK
A11: Simulado 01 | B11: 3 | C11: 7ª Fase | D11: E | E11: 33 | F11: 25 | G11: =IF(E11=0,"",F11/E11) | H11: OK
A12: Simulado 01 | B12: 3 | C12: 10ª Fase | D12: E | E12: 31 | F12: 18 | G12: =IF(E12=0,"",F12/E12) | H12: OK
A13: Simulado 01 | B13: 3 | C13: 11ª Fase | D13: E | E13: 27 | F13: 17 | G13: =IF(E13=0,"",F13/E13) | H13: OK
... A93: Simulado 01 | B93: 23 | C93: 11ª Fase | D93: D | E93: 27 | F93: 21 | G93: =IF(E93=0,"",F93/E93) | H93: OK
A94: Simulado 01 | B94: 24 | C94: 6ª Fase | D94: A | H94: ANULADA - sem dados no dashboard
A95: Simulado 01 | B95: 24 | C95: 7ª Fase | D95: A | H95: ANULADA - sem dados no dashboard
A96: Simulado 01 | B96: 24 | C96: 10ª Fase | D96: A | H96: ANULADA - sem dados no dashboard
A97: Simulado 01 | B97: 24 | C97: 11ª Fase | D97: A | H97: ANULADA - sem dados no dashboard
A98: Simulado 01 | B98: 25 | C98: 6ª Fase | D98: E | E98: 27 | F98: 14 | G98: =IF(E98=0,"",F98/E98) | H98: OK
A99: Simulado 01 | B99: 25 | C99: 7ª Fase | D99: E | E99: 33 | F99: 19 | G99: =IF(E99=0,"",F99/E99) | H99: OK
A100: Simulado 01 | B100: 25 | C100: 10ª Fase | D100: E | E100: 31 | F100: 19 | G100: =IF(E100=0,"",F100/E100) | H100: OK
A101: Simulado 01 | B101: 25 | C101: 11ª Fase | D101: E | E101: 27 | F101: 16 | G101: =IF(E101=0,"",F101/E101) | H101: OK
A102: Simulado 01 | B102: 26 | C102: 6ª Fase | D102: D | E102: 27 | F102: 19 | G102: =IF(E102=0,"",F102/E102) | H102: OK
A103: Simulado 01 | B103: 26 | C103: 7ª Fase | D103: D | E103: 33 | F103: 25 | G103: =IF(E103=0,"",F103/E103) | H103: OK
A104: Simulado 01 | B104: 26 | C104: 10ª Fase | D104: D | E104: 31 | F104: 24 | G104: =IF(E104=0,"",F104/E104) | H104: OK
A105: Simulado 01 | B105: 26 | C105: 11ª Fase | D105: D | E105: 27 | F105: 23 | G105: =IF(E105=0,"",F105/E105) | H105: OK
A106: Simulado 01 | B106: 27 | C106: 6ª Fase | D106: E | E106: 27 | F106: 9 | G106: =IF(E106=0,"",F106/E106) | H106: OK
A107: Simulado 01 | B107: 27 | C107: 7ª Fase | D107: E | E107: 33 | F107: 16 | G107: =IF(E107=0,"",F107/E107) | H107: OK
A108: Simulado 01 | B108: 27 | C108: 10ª Fase | D108: E | E108: 31 | F108: 17 | G108: =IF(E108=0,"",F108/E108) | H108: OK
A109: Simulado 01 | B109: 27 | C109: 11ª Fase | D109: E | E109: 27 | F109: 12 | G109: =IF(E109=0,"",F109/E109) | H109: OK
... A401: Simulado 02 | B401: 60 | C401: 11ª Fase | D401: C | E401: 29 | F401: 19 | G401: =IF(E401=0,"",F401/E401) | H401: OK

Sheet Distribuição respostas
A1: Simulado | B1: Questão | C1: Fase | D1: Alternativa | E1: É o gabarito? | F1: Alunos na fase | G1: Nº de respostas | H1: % das respostas
A2: Simulado 01 | B2: 1 | C2: 6ª Fase | D2: A | E2: Não | F2: 27 | G2: 0 | H2: =IF(F2=0,"",G2/F2)
A3: Simulado 01 | B3: 1 | C3: 6ª Fase | D3: B | E3: Não | F3: 27 | G3: 0 | H3: =IF(F3=0,"",G3/F3)
A4: Simulado 01 | B4: 1 | C4: 6ª Fase | D4: C | E4: Não | F4: 27 | G4: 1 | H4: =IF(F4=0,"",G4/F4)
A5: Simulado 01 | B5: 1 | C5: 6ª Fase | D5: D | E5: Não | F5: 27 | G5: 2 | H5: =IF(F5=0,"",G5/F5)
A6: Simulado 01 | B6: 1 | C6: 6ª Fase | D6: E | E6: Sim | F6: 27 | G6: 24 | H6: =IF(F6=0,"",G6/F6)
A7: Simulado 01 | B7: 1 | C7: 7ª Fase | D7: A | E7: Não | F7: 33 | G7: 0 | H7: =IF(F7=0,"",G7/F7)
A8: Simulado 01 | B8: 1 | C8: 7ª Fase | D8: B | E8: Não | F8: 33 | G8: 0 | H8: =IF(F8=0,"",G8/F8)
A9: Simulado 01 | B9: 1 | C9: 7ª Fase | D9: C | E9: Não | F9: 33 | G9: 0 | H9: =IF(F9=0,"",G9/F9)
A10: Simulado 01 | B10: 1 | C10: 7ª Fase | D10: D | E10: Não | F10: 33 | G10: 1 | H10: =IF(F10=0,"",G10/F10)
A11: Simulado 01 | B11: 1 | C11: 7ª Fase | D11: E | E11: Sim | F11: 33 | G11: 32 | H11: =IF(F11=0,"",G11/F11)
A12: Simulado 01 | B12: 1 | C12: 10ª Fase | D12: A | E12: Não | F12: 31 | G12: 0 | H12: =IF(F12=0,"",G12/F12)
A13: Simulado 01 | B13: 1 | C13: 10ª Fase | D13: B | E13: Não | F13: 31 | G13: 0 | H13: =IF(F13=0,"",G13/F13)
... A1769: Simulado 02 | B1769: 60 | C1769: 11ª Fase | D1769: D | E1769: Não | F1769: 29 | G1769: 0 | H1769: =IF(F1769=0,"",G1769/F1769)

Sheet Resumo por fase
A1: Simulado | B1: Fase | C1: Nº de alunos | D1: Base do % (questões) | E1: Média de acertos | F1: % médio | G1: Mediana | H1: Mínimo | I1: Máximo | J1: Desvio-padrão | K1: Amplitude
A2: Simulado 01 | B2: 6ª Fase | C2: 27 | D2: 39 | E2: =AVERAGE(Alunos!$D$2:$D$28) | F2: =E2/D2 | G2: =MEDIAN(Alunos!$D$2:$D$28) | H2: =MIN(Alunos!$D$2:$D$28) | I2: =MAX(Alunos!$D$2:$D$28) | J2: =STDEV(Alunos!$D$2:$D$28) | K2: =I2-H2
A3: Simulado 01 | B3: 7ª Fase | C3: 33 | D3: 39 | E3: =AVERAGE(Alunos!$D$29:$D$61) | F3: =E3/D3 | G3: =MEDIAN(Alunos!$D$29:$D$61) | H3: =MIN(Alunos!$D$29:$D$61) | I3: =MAX(Alunos!$D$29:$D$61) | J3: =STDEV(Alunos!$D$29:$D$61) | K3: =I3-H3
A4: Simulado 01 | B4: 10ª Fase | C4: 31 | D4: 39 | E4: =AVERAGE(Alunos!$D$62:$D$92) | F4: =E4/D4 | G4: =MEDIAN(Alunos!$D$62:$D$92) | H4: =MIN(Alunos!$D$62:$D$92) | I4: =MAX(Alunos!$D$62:$D$92) | J4: =STDEV(Alunos!$D$62:$D$92) | K4: =I4-H4
A5: Simulado 01 | B5: 11ª Fase | C5: 27 | D5: 39 | E5: =AVERAGE(Alunos!$D$93:$D$119) | F5: =E5/D5 | G5: =MEDIAN(Alunos!$D$93:$D$119) | H5: =MIN(Alunos!$D$93:$D$119) | I5: =MAX(Alunos!$D$93:$D$119) | J5: =STDEV(Alunos!$D$93:$D$119) | K5: =I5-H5
A6: Simulado 02 | B6: 6ª Fase | C6: 28 | D6: 60 | E6: =AVERAGE(Alunos!$D$120:$D$147) | F6: =E6/D6 | G6: =MEDIAN(Alunos!$D$120:$D$147) | H6: =MIN(Alunos!$D$120:$D$147) | I6: =MAX(Alunos!$D$120:$D$147) | J6: =STDEV(Alunos!$D$120:$D$147) | K6: =I6-H6
A7: Simulado 02 | B7: 7ª Fase | C7: 32 | D7: 60 | E7: =AVERAGE(Alunos!$D$148:$D$179) | F7: =E7/D7 | G7: =MEDIAN(Alunos!$D$148:$D$179) | H7: =MIN(Alunos!$D$148:$D$179) | I7: =MAX(Alunos!$D$148:$D$179) | J7: =STDEV(Alunos!$D$148:$D$179) | K7: =I7-H7
A8: Simulado 02 | B8: 10ª Fase | C8: 31 | D8: 60 | E8: =AVERAGE(Alunos!$D$180:$D$210) | F8: =E8/D8 | G8: =MEDIAN(Alunos!$D$180:$D$210) | H8: =MIN(Alunos!$D$180:$D$210) | I8: =MAX(Alunos!$D$180:$D$210) | J8: =STDEV(Alunos!$D$180:$D$210) | K8: =I8-H8
A9: Simulado 02 | B9: 11ª Fase | C9: 29 | D9: 60 | E9: =AVERAGE(Alunos!$D$211:$D$239) | F9: =E9/D9 | G9: =MEDIAN(Alunos!$D$211:$D$239) | H9: =MIN(Alunos!$D$211:$D$239) | I9: =MAX(Alunos!$D$211:$D$239) | J9: =STDEV(Alunos!$D$211:$D$239) | K9: =I9-H9

Sheet Comparativo S01 x S02
A1: Nome do acadêmico | B1: Fase | C1: Acertos S01 (base 39) | D1: % S01 | E1: Acertos S02 (base 60) | F1: % S02 | G1: Variação (p.p.) | H1: Presença
A2: Abraham Lincoln Galdino Costa | B2: 7ª Fase | C2: 23 | D2: =IF(C2="","",C2/39) | E2: 38 | F2: =IF(E2="","",E2/60) | G2: =IF(OR(C2="",E2=""),"",(F2-D2)*100) | H2: Nos dois simulados
A3: Aline Agostini | B3: 10ª Fase | C3: 27 | D3: =IF(C3="","",C3/39) | E3: 38 | F3: =IF(E3="","",E3/60) | G3: =IF(OR(C3="",E3=""),"",(F3-D3)*100) | H3: Nos dois simulados
A4: Amanda de Matos da Silva | B4: 6ª Fase | C4: 26 | D4: =IF(C4="","",C4/39) | E4: 37 | F4: =IF(E4="","",E4/60) | G4: =IF(OR(C4="",E4=""),"",(F4-D4)*100) | H4: Nos dois simulados
A5: Amanda Figueiredo Meneghetti | B5: 6ª Fase | C5: 23 | D5: =IF(C5="","",C5/39) | E5: 34 | F5: =IF(E5="","",E5/60) | G5: =IF(OR(C5="",E5=""),"",(F5-D5)*100) | H5: Nos dois simulados
A6: Amanda Luisa Batista | B6: 11ª Fase | C6: 29 | D6: =IF(C6="","",C6/39) | F6: =IF(E6="","",E6/60) | G6: =IF(OR(C6="",E6=""),"",(F6-D6)*100) | H6: Só no Simulado 01
A7: Ana Carolina Assis Benvenutti | B7: 11ª Fase | C7: 28 | D7: =IF(C7="","",C7/39) | F7: =IF(E7="","",E7/60) | G7: =IF(OR(C7="",E7=""),"",(F7-D7)*100) | H7: Só no Simulado 01
A8: Ana Flavia Losi | B8: 11ª Fase | C8: 26 | D8: =IF(C8="","",C8/39) | E8: 42 | F8: =IF(E8="","",E8/60) | G8: =IF(OR(C8="",E8=""),"",(F8-D8)*100) | H8: Nos dois simulados
A9: Ana Luiza Tenfen | B9: 7ª Fase | C9: 27 | D9: =IF(C9="","",C9/39) | E9: 38 | F9: =IF(E9="","",E9/60) | G9: =IF(OR(C9="",E9=""),"",(F9-D9)*100) | H9: Nos dois simulados
A10: Antonella Gubert Verch | B10: 7ª Fase | C10: 25 | D10: =IF(C10="","",C10/39) | E10: 34 | F10: =IF(E10="","",E10/60) | G10: =IF(OR(C10="",E10=""),"",(F10-D10)*100) | H10: Nos dois simulados
A11: Antonia Dittrich Nova Curz Bandeira | B11: 11ª Fase | D11: =IF(C11="","",C11/39) | E11: 40 | F11: =IF(E11="","",E11/60) | G11: =IF(OR(C11="",E11=""),"",(F11-D11)*100) | H11: Só no Simulado 02
A12: Augusto Henrique Gamba | B12: 7ª Fase | C12: 21 | D12: =IF(C12="","",C12/39) | E12: 40 | F12: =IF(E12="","",E12/60) | G12: =IF(OR(C12="",E12=""),"",(F12-D12)*100) | H12: Nos dois simulados
A13: Bernardo Martins Zonta | B13: 11ª Fase | C13: 27 | D13: =IF(C13="","",C13/39) | E13: 37 | F13: =IF(E13="","",E13/60) | G13: =IF(OR(C13="",E13=""),"",(F13-D13)*100) | H13: Nos dois simulados
A14: Brenda Cristina Albino | B14: 10ª Fase | C14: 28 | D14: =IF(C14="","",C14/39) | E14: 42 | F14: =IF(E14="","",E14/60) | G14: =IF(OR(C14="",E14=""),"",(F14-D14)*100) | H14: Nos dois simulados
A15: Bruna Gonzalez Nejm | B15: 7ª Fase | C15: 26 | D15: =IF(C15="","",C15/39) | E15: 39 | F15: =IF(E15="","",E15/60) | G15: =IF(OR(C15="",E15=""),"",(F15-D15)*100) | H15: Nos dois simulados
A16: Bárbara Letícia Armiliato | B16: 6ª Fase | C16: 22 | D16: =IF(C16="","",C16/39) | E16: 28 | F16: =IF(E16="","",E16/60) | G16: =IF(OR(C16="",E16=""),"",(F16-D16)*100) | H16: Nos dois simulados
A17: Caio Mateus Garlini | B17: 11ª Fase | C17: 27 | D17: =IF(C17="","",C17/39) | E17: 38 | F17: =IF(E17="","",E17/60) | G17: =IF(OR(C17="",E17=""),"",(F17-D17)*100) | H17: Nos dois simulados
A18: Camila Cabral de Souza | B18: 10ª Fase | C18: 22 | D18: =IF(C18="","",C18/39) | E18: 40 | F18: =IF(E18="","",E18/60) | G18: =IF(OR(C18="",E18=""),"",(F18-D18)*100) | H18: Nos dois simulados
A19: Camila Debatin | B19: 10ª Fase | C19: 23 | D19: =IF(C19="","",C19/39) | E19: 22 | F19: =IF(E19="","",E19/60) | G19: =IF(OR(C19="",E19=""),"",(F19-D19)*100) | H19: Nos dois simulados
A20: Carl Zolet Jonck | B20: 7ª Fase | C20: 21 | D20: =IF(C20="","",C20/39) | E20: 38 | F20: =IF(E20="","",E20/60) | G20: =IF(OR(C20="",E20=""),"",(F20-D20)*100) | H20: Nos dois simulados
A21: Carla Bonacolsi | B21: 6ª Fase | C21: 18 | D21: =IF(C21="","",C21/39) | E21: 31 | F21: =IF(E21="","",E21/60) | G21: =IF(OR(C21="",E21=""),"",(F21-D21)*100) | H21: Nos dois simulados
A22: Carolina Signori Duarte | B22: 11ª Fase | C22: 27 | D22: =IF(C22="","",C22/39) | E22: 37 | F22: =IF(E22="","",E22/60) | G22: =IF(OR(C22="",E22=""),"",(F22-D22)*100) | H22: Nos dois simulados
A23: Cauã Eduardo Eibel | B23: 6ª Fase | C23: 22 | D23: =IF(C23="","",C23/39) | E23: 39 | F23: =IF(E23="","",E23/60) | G23: =IF(OR(C23="",E23=""),"",(F23-D23)*100) | H23: Nos dois simulados
A24: Daniely Aparecida Steinheisen | B24: 10ª Fase | C24: 27 | D24: =IF(C24="","",C24/39) | E24: 29 | F24: =IF(E24="","",E24/60) | G24: =IF(OR(C24="",E24=""),"",(F24-D24)*100) | H24: Nos dois simulados
A25: Danton Capistrano Ferreira | B25: 11ª Fase | C25: 28 | D25: =IF(C25="","",C25/39) | F25: =IF(E25="","",E25/60) | G25: =IF(OR(C25="",E25=""),"",(F25-D25)*100) | H25: Só no Simulado 01
A26: Eduarda Ferreira Merigo | B26: 11ª Fase | C26: 23 | D26: =IF(C26="","",C26/39) | F26: =IF(E26="","",E26/60) | G26: =IF(OR(C26="",E26=""),"",(F26-D26)*100) | H26: Só no Simulado 01
A27: Eduardo Jacó Goedert | B27: 6ª Fase | C27: 19 | D27: =IF(C27="","",C27/39) | E27: 36 | F27: =IF(E27="","",E27/60) | G27: =IF(OR(C27="",E27=""),"",(F27-D27)*100) | H27: Nos dois simulados
A28: Eduardo Lorenço Moreira | B28: 11ª Fase | C28: 21 | D28: =IF(C28="","",C28/39) | E28: 33 | F28: =IF(E28="","",E28/60) | G28: =IF(OR(C28="",E28=""),"",(F28-D28)*100) | H28: Nos dois simulados
A29: Eduardo Miguel Panizzon | B29: 10ª Fase | C29: 26 | D29: =IF(C29="","",C29/39) | E29: 46 | F29: =IF(E29="","",E29/60) | G29: =IF(OR(C29="",E29=""),"",(F29-D29)*100) | H29: Nos dois simulados
A30: Elisa Patzlaff | B30: 11ª Fase | C30: 23 | D30: =IF(C30="","",C30/39) | E30: 42 | F30: =IF(E30="","",E30/60) | G30: =IF(OR(C30="",E30=""),"",(F30-D30)*100) | H30: Nos dois simulados
A31: Emanuela Tenfen | B31: 7ª Fase | C31: 19 | D31: =IF(C31="","",C31/39) | E31: 25 | F31: =IF(E31="","",E31/60) | G31: =IF(OR(C31="",E31=""),"",(F31-D31)*100) | H31: Nos dois simulados
A32: Emily Martins Arruda | B32: 7ª Fase | C32: 25 | D32: =IF(C32="","",C32/39) | E32: 33 | F32: =IF(E32="","",E32/60) | G32: =IF(OR(C32="",E32=""),"",(F32-D32)*100) | H32: Nos dois simulados
A33: Fernando Lima Nogueira | B33: 7ª Fase | C33: 18 | D33: =IF(C33="","",C33/39) | E33: 28 | F33: =IF(E33="","",E33/60) | G33: =IF(OR(C33="",E33=""),"",(F33-D33)*100) | H33: Nos dois simulados
A34: Gabriel Borella Rosado | B34: 7ª Fase | C34: 18 | D34: =IF(C34="","",C34/39) | E34: 25 | F34: =IF(E34="","",E34/60) | G34: =IF(OR(C34="",E34=""),"",(F34-D34)*100) | H34: Nos dois simulados
A35: Gabriel Olivo Leandro | B35: 10ª Fase | C35: 26 | D35: =IF(C35="","",C35/39) | E35: 34 | F35: =IF(E35="","",E35/60) | G35: =IF(OR(C35="",E35=""),"",(F35-D35)*100) | H35: Nos dois simulados
A36: Gabriela Lucia Imhoff | B36: 7ª Fase | C36: 26 | D36: =IF(C36="","",C36/39) | E36: 36 | F36: =IF(E36="","",E36/60) | G36: =IF(OR(C36="",E36=""),"",(F36-D36)*100) | H36: Nos dois simulados
A37: Gabriela Luiza Cezar | B37: 7ª Fase | C37: 23 | D37: =IF(C37="","",C37/39) | E37: 37 | F37: =IF(E37="","",E37/60) | G37: =IF(OR(C37="",E37=""),"",(F37-D37)*100) | H37: Nos dois simulados
A38: Gabriela Tambosi Catafesta | B38: 7ª Fase | C38: 25 | D38: =IF(C38="","",C38/39) | E38: 36 | F38: =IF(E38="","",E38/60) | G38: =IF(OR(C38="",E38=""),"",(F38-D38)*100) | H38: Nos dois simulados
A39: Geisa Maritsa Wippel Schramm | B39: 11ª Fase | D39: =IF(C39="","",C39/39) | E39: 35 | F39: =IF(E39="","",E39/60) | G39: =IF(OR(C39="",E39=""),"",(F39-D39)*100) | H39: Só no Simulado 02
A40: Gercino de Matos Neto | B40: 7ª Fase | C40: 24 | D40: =IF(C40="","",C40/39) | E40: 39 | F40: =IF(E40="","",E40/60) | G40: =IF(OR(C40="",E40=""),"",(F40-D40)*100) | H40: Nos dois simulados
...
